Workbook

Sheet Timesheet Month Year
C2: Timesheet Template | I2: CODE | K2: SP-OU-003-F-APS
I3: VERSION | K3: 4
I4: APPROVAL DATE
C5: *Please download a copy of this document before editing it
B7: Payment Period: | C7: 45870 | I7: Approved by:
B8: Work week | C8: Sunday-Thursday
B9: Name: | C9: [include your name] | I9: REVISION DATE | K9: 45652
B10: Roles:
B11: Corresponding Unit:
B13: Project (Contract Code) | C13: Client / Project | D13: Role | E13: Work Description | F13: =C7 -> 45870 | G13: =F13+1 -> 45871 | H13: =G13+1 -> 45872 | I13: =H13+1 -> 45873 | J13: =I13+1 -> 45874 | K13: =J13+1 -> 45875 | L13: =K13+1 -> 45876 | M13: =L13+1 -> 45877 | N13: =M13+1 -> 45878 | ... AJ13: =AI13+1 -> 45900 | AK13: Total
C14: =IFERROR(VLOOKUP($B14,'Restricted 2 - available prjcts'!$A$2:$B$86,2,0),"-") -> - | AK14: =SUM(F14:AJ14) -> 0
C15: =IFERROR(VLOOKUP($B15,'Restricted 2 - available prjcts'!$A$2:$B$86,2,0),"-") -> - | AK15: =SUM(F15:AJ15) -> 0
C16: =IFERROR(VLOOKUP($B16,'Restricted 2 - available prjcts'!$A$2:$B$86,2,0),"-") -> - | AK16: =SUM(F16:AJ16) -> 0
C17: =IFERROR(VLOOKUP($B17,'Restricted 2 - available prjcts'!$A$2:$B$86,2,0),"-") -> - | AK17: =SUM(F17:AJ17) -> 0
C18: =IFERROR(VLOOKUP($B18,'Restricted 2 - available prjcts'!$A$2:$B$86,2,0),"-") -> - | AK18: =SUM(F18:AJ18) -> 0
C19: =IFERROR(VLOOKUP($B19,'Restricted 2 - available prjcts'!$A$2:$B$86,2,0),"-") -> - | AK19: =SUM(F19:AJ19) -> 0
C20: =IFERROR(VLOOKUP($B20,'Restricted 2 - available prjcts'!$A$2:$B$86,2,0),"-") -> - | AK20: =SUM(F20:AJ20) -> 0
C21: =IFERROR(VLOOKUP($B21,'Restricted 2 - available prjcts'!$A$2:$B$86,2,0),"-") -> - | AK21: =SUM(F21:AJ21) -> 0
C22: =IFERROR(VLOOKUP($B22,'Restricted 2 - available prjcts'!$A$2:$B$86,2,0),"-") -> - | AK22: =SUM(F22:AJ22) -> 0
C23: =IFERROR(VLOOKUP($B23,'Restricted 2 - available prjcts'!$A$2:$B$86,2,0),"-") -> - | AK23: =SUM(F23:AJ23) -> 0
C24: =IFERROR(VLOOKUP($B24,'Restricted 2 - available prjcts'!$A$2:$B$86,2,0),"-") -> - | AK24: =SUM(F24:AJ24) -> 0
C25: =IFERROR(VLOOKUP($B25,'Restricted 2 - available prjcts'!$A$2:$B$86,2,0),"-") -> - | AK25: =SUM(F25:AJ25) -> 0
... C28: =IFERROR(VLOOKUP($B28,'Restricted 2 - available prjcts'!$A$2:$B$86,2,0),"-") -> - | AK28: =SUM(F28:AJ28) -> 0
E29: Total Hours | F29: =SUM(F14:F28) -> 0 | G29: =SUM(G14:G28) -> 0 | H29: =SUM(H14:H28) -> 0 | I29: =SUM(I14:I28) -> 0 | J29: =SUM(J14:J28) -> 0 | K29: =SUM(K14:K28) -> 0 | L29: =SUM(L14:L28) -> 0 | M29: =SUM(M14:M28) -> 0 | ... AK29: =SUM(AK14:AK28) -> 0
E31: Time off (Type)
E32: Annual Leave / RnR | AK32: =SUM(F32:AJ32) -> 0
E33: Sick Leave | AK33: =SUM(F33:AJ33) -> 0
B34: Do not modify B34 | E34: National Holidays (Public Holidays) | AK34: =SUM(F34:AJ34) -> 0
E35: Leave without Pay (LWOP) | AK35: =SUM(F35:AJ35) -> 0
B36: =C9&" "&B38&" "&"timesheet" -> [include your name] 08-2025 timesheet | E36: Total | F36: =SUM(F32:F35) -> 0 | G36: =SUM(G32:G35) -> 0 | H36: =SUM(H32:H35) -> 0 | I36: =SUM(I32:I35) -> 0 | J36: =SUM(J32:J35) -> 0 | K36: =SUM(K32:K35) -> 0 | L36: =SUM(L32:L35) -> 0 | M36: =SUM(M32:M35) -> 0 | ... AK36: =SUM(AK32:AK35) -> 0
B38: =TEXT(C7,"mm-yyyy") -> 08-2025
F40: Submission | H40: Name / Signature | L40: Position | P40: Date
F42: Approval | H42: Name / Signature | L42: Position | P42: Date
C56: =SUM(C41:C55) -> 0
B59: Grand Total
B60: Total hours | C60: =AK29 -> 0
B61: =E32 -> Annual Leave / RnR | C61: =AK32 -> 0
B62: =E33 -> Sick Leave | C62: =AK33 -> 0
B63: =E34 -> National Holidays (Public Holidays) | C63: =AK34 -> 0
B64: Total payable hours | C64: =SUM(C60:C63) -> 0
...

Sheet Restricted - not in use
A1: Months | C1: Contracts | D1: Clients | E1: Work week | F1: Consultants* | G1: Supervisors* | H1: *This info is available from payment berakdown sheet
A5: 45658 | C5: APS-078 | E5: Monday-Friday | F5: Wael Rahhel | G5: Maria Melo Torres
A6: 45689 | C6: APS-082 | E6: Sunday-Thursday | F6: Najdat Abdeen | G6: Maria Melo Torres
A7: 45717 | C7: APS-083 | F7: Francis Rivera | G7: Agron Ferati
A8: 45748 | C8: APS-084 | F8: Erik Jan Lode | G8: Agron Ferati
A9: 45778 | C9: APS-093 | F9: Samer Emarili | G9: Maria Melo Torres
A10: 45809 | C10: APS-096
A11: 45839 | C11: APS-098 | F11: Kasem Al Ahmad | G11: Agron Ferati Relevant Sr.PM
A12: 45870 | C12: APS-102 | F12: Ueda Osmani | G12: Ledian Shera Ardi Mejzini
A13: 45901 | C13: APS-103 | F13: Chiara Veronica Carli | G13: Agron Ferati
A14: 45931 | C14: APS-106 | F14: Samir Elagra | G14: Agron Ferati
A15: 45962 | C15: APS-109 | F15: Catherine Pacheco-Olivar | G15: Francis Rivera
A16: 45992 | C16: APS-110 | F16: Huda Khallouf | G16: Agron Ferati
A17: 46023 | C17: APS-114 | F17: Aboubacar Diallo | G17: Agron Ferati
A18: 46054 | C18: APS-116 | F18: Ledian Shera | G18: Agron Ferati Ardi Mejzini
A19: 46082 | C19: APS-118 | F19: Ehab Zaghloul Kotb | G19: Agron Ferati
A20: 46113 | C20: APS-119 | F20: Antonio Suarez | G20: Francis Rivera
A21: 46143 | C21: APS-120 | F21: Maria Teresa Ramos Acosta | G21: Francis Rivera
A22: 46174 | C22: APS-121 | F22: Melike Ozberk | G22: Agron Ferati
A23: 46204 | C23: APS-123
A24: 46235 | C24: APS-124 | F24: Clara Di Dio | G24: Maria Melo Torres Agron Ferati
A25: 46266 | C25: APS-125 | F25: Akhil Kakkar | G25: Marko Runjic
A26: 46296 | C26: APS-126 | F26: Juliana Loaiza Rincón | G26: Maria Melo Torres
A27: 46327 | C27: APS-127 | F27: Solange Gacuti | G27: Marko Runjic
A28: 46357 | C28: APS-128 | F28: Andrea Campos Villarraga | G28: Maria Melo Torres Data Analsis Unit Manager
A29: 46388 | C29: APS-129 | F29: Liliana Martínez Rosales | G29: Maria Teresa Ramos
A30: 46419 | C30: APS-130 | F30: Gertrudys Cedeno | G30: Francis Rivera
A31: 46447 | C31: APS-131 | F31: Irene Petkoff | G31: Francis Rivera
A32: 46478 | C32: APS-132 | F32: Richard Hocking | G32: Chiara Carli Agron Ferati
A33: 46508 | C33: APS-133 | F33: Madison Rose | G33: Amina Ferati
A34: 46539 | C34: APS-134 | F34: Mouna Baker | G34: Agron?
A35: 46569 | C35: APS-135 | F35: Javier Mayorca | G35: Agron
... A51: 47058 | C51: APS-151 | F51: Angie Montenegro Alvarado | G51: Maria Melo Torres Agron Ferati
A52: 47088 | C52: APS-152 | F52: Odonchimeg Tsevegmid
A53: 47119 | C53: APS-153 | F53: Rebecca O`Keefe | G53: Amina Ferati
A54: 47150 | C54: APS-154 | F54: Alejandro Garcia Flores | G54: Ledian Shera Agron Ferati
A55: 47178 | C55: APS-155 | F55: Elhaj Mustafa Ali | G55: Samir Elagra
A56: 47209 | C56: APS-156 | F56: Eltayeb Mohamedain Abdalla Mohamdain | G56: Samir Elagra
A57: 47239 | C57: APS-157 | F57: Abdelghani Ahmed Hussein | G57: Samir Elagra
A58: 47270 | C58: APS-158 | F58: Mona Mohamed Taha Ayoub
...

Sheet Restricted 2 - available prjcts
A1: PROJECT CODE | B1: CLIENT
A2: APS-000-01 | B2: Finance / Admin / HR Unit
A3: APS-000-06 | B3: Operations Unit
A4: APS-000-11 | B4: Business Development Unit
A5: APS-000-12 | B5: Data Analysis Unit
A6: APS-000-13 | B6: Communication, Design And Visibility Unit
A7: APS-000-15 | B7: Technology (KAP products) Unit
A8: APS-000-33 | B8: Program Management Unit
A9: APS-000-34 | B9: Technical Unit
A10: APS-000-35 | B10: Field Monitoring and Data Collection Unit
A11: APS-000-36 | B11: Legal and Compliance Unit
A12: YEM-002-017 | B12: UNICEF Yemen PO 43356770
... A33: APS-148 | B33: EnCompass LLC
A34: APS-149
A35: APS-150 | B35: Swiss Solidarity (SwS)
A36: APS-151
A37: APS-152
A38: APS-153
A39: APS-154
A40: APS-155
A41: APS-156
A42: APS-157
A43: APS-158
A44: APS-159
A45: APS-160
A46: APS-161
A47: APS-162
... A105: APS-220
